<?xml version="1.0" encoding="utf-8"?>
<!-- This URDF was automatically created by SolidWorks to URDF Exporter! Originally created by Stephen Brawner (brawner@gmail.com) 
     Commit Version: 1.5.1-0-g916b5db  Build Version: 1.5.7152.31018
     For more information, please see http://wiki.ros.org/sw_urdf_exporter -->
<robot
  name="new_model">
  <link
    name="base_link">
    <inertial>
      <origin
        xyz="-0.00122507959535201 -0.0132142522574721 0.158187880538494"
        rpy="0 0 0" />
      <mass
        value="5.04599768700966" />
      <inertia
        ixx="0.0199585188421208"
        ixy="8.49633695615799E-07"
        ixz="3.57924483879844E-07"
        iyy="0.0133780567917246"
        iyz="-8.69413175238509E-06"
        izz="0.0204011323429144" />
    </inertial>
    <visual>
      <origin
        xyz="0 0 0"
        rpy="0 0 0" />
      <geometry>
        <mesh
          filename="package://new_model/meshes/base_link.STL" />
      </geometry>
      <material
        name="">
        <color
          rgba="0.752941176470588 0.752941176470588 0.752941176470588 1" />
      </material>
    </visual>
    <collision>
      <origin
        xyz="0 0 0"
        rpy="0 0 0" />
      <geometry>
        <mesh
          filename="package://new_model/meshes/base_link.STL" />
      </geometry>
    </collision>
  </link>
  <link
    name="RFS">
    <inertial>
      <origin
        xyz="0.13547 0.086849 0.092683"
        rpy="0 0 0" />
      <mass
        value="0.26437" />
      <inertia
        ixx="3.2075E-05"
        ixy="-1.5645E-07"
        ixz="1.6485E-08"
        iyy="6.2207E-05"
        iyz="-2.9641E-09"
        izz="6.2915E-05" />
    </inertial>
    <visual>
      <origin
        xyz="0 0 0"
        rpy="0 0 0" />
      <geometry>
        <mesh
          filename="package://new_model/meshes/RFS.STL" />
      </geometry>
      <material
        name="">
        <color
          rgba="0.75294 0.75294 0.75294 1" />
      </material>
    </visual>
    <collision>
      <origin
        xyz="0 0 0"
        rpy="0 0 0" />
      <geometry>
        <mesh
          filename="package://new_model/meshes/RFS.STL" />
      </geometry>
    </collision>
  </link>
  <joint
    name="right_front_suspension"
    type="prismatic">
    <origin
      xyz="0 0 0"
      rpy="0 0 0" />
    <parent
      link="base_link" />
    <child
      link="RFS" />
    <axis
      xyz="0 0 1" />
    <limit
      lower="0"
      upper="0"
      effort="0"
      velocity="0" />
  </joint>
  <link
    name="RFW">
    <inertial>
      <origin
        xyz="0.18943 0.1001 0.062199"
        rpy="0 0 0" />
      <mass
        value="0.19359" />
      <inertia
        ixx="0.00025308"
        ixy="-5.171E-21"
        ixz="2.2481E-36"
        iyy="0.00013682"
        iyz="-4.286E-37"
        izz="0.00013682" />
    </inertial>
    <visual>
      <origin
        xyz="0 0 0"
        rpy="0 0 0" />
      <geometry>
        <mesh
          filename="package://new_model/meshes/RFW.STL" />
      </geometry>
      <material
        name="">
        <color
          rgba="1 1 1 1" />
      </material>
    </visual>
    <collision>
      <origin
        xyz="0 0 0"
        rpy="0 0 0" />
      <geometry>
        <mesh
          filename="package://new_model/meshes/RFW.STL" />
      </geometry>
    </collision>
  </link>
  <joint
    name="right_front_wheel"
    type="continuous">
    <origin
      xyz="0 0 0"
      rpy="0 0 0" />
    <parent
      link="RFS" />
    <child
      link="RFW" />
    <axis
      xyz="1 0 0" />
    <limit
      effort="3.1"
      velocity="7" />
  </joint>
  <link
    name="LFS">
    <inertial>
      <origin
        xyz="-0.13547 0.086849 0.092691"
        rpy="0 0 0" />
      <mass
        value="0.26437" />
      <inertia
        ixx="3.2075E-05"
        ixy="1.5645E-07"
        ixz="1.6485E-08"
        iyy="6.2207E-05"
        iyz="2.9641E-09"
        izz="6.2915E-05" />
    </inertial>
    <visual>
      <origin
        xyz="0 0 0"
        rpy="0 0 0" />
      <geometry>
        <mesh
          filename="package://new_model/meshes/LFS.STL" />
      </geometry>
      <material
        name="">
        <color
          rgba="0.75294 0.75294 0.75294 1" />
      </material>
    </visual>
    <collision>
      <origin
        xyz="0 0 0"
        rpy="0 0 0" />
      <geometry>
        <mesh
          filename="package://new_model/meshes/LFS.STL" />
      </geometry>
    </collision>
  </link>
  <joint
    name="left_front_suspension"
    type="prismatic">
    <origin
      xyz="0 0 0"
      rpy="0 0 0" />
    <parent
      link="base_link" />
    <child
      link="LFS" />
    <axis
      xyz="0 0 1" />
    <limit
      lower="0"
      upper="0"
      effort="0"
      velocity="0" />
  </joint>
  <link
    name="LFW">
    <inertial>
      <origin
        xyz="-0.18943 0.1001 0.062197"
        rpy="0 0 0" />
      <mass
        value="0.19359" />
      <inertia
        ixx="0.00025308"
        ixy="-3.2321E-19"
        ixz="8.5767E-19"
        iyy="0.00013682"
        iyz="2.1137E-20"
        izz="0.00013682" />
    </inertial>
    <visual>
      <origin
        xyz="0 0 0"
        rpy="0 0 0" />
      <geometry>
        <mesh
          filename="package://new_model/meshes/LFW.STL" />
      </geometry>
      <material
        name="">
        <color
          rgba="1 1 1 1" />
      </material>
    </visual>
    <collision>
      <origin
        xyz="0 0 0"
        rpy="0 0 0" />
      <geometry>
        <mesh
          filename="package://new_model/meshes/LFW.STL" />
      </geometry>
    </collision>
  </link>
  <joint
    name="left_front_wheel"
    type="continuous">
    <origin
      xyz="0 0 0"
      rpy="0 0 0" />
    <parent
      link="LFS" />
    <child
      link="LFW" />
    <axis
      xyz="1 0 0" />
    <limit
      effort="3.1"
      velocity="7" />
  </joint>
  <link
    name="RBS">
    <inertial>
      <origin
        xyz="0.12676 -0.083501 0.099498"
        rpy="0 0 0" />
      <mass
        value="0.19701" />
      <inertia
        ixx="1.688E-05"
        ixy="2.2931E-20"
        ixz="-2.235E-19"
        iyy="5.0552E-05"
        iyz="-2.687E-21"
        izz="4.6911E-05" />
    </inertial>
    <visual>
      <origin
        xyz="0 0 0"
        rpy="0 0 0" />
      <geometry>
        <mesh
          filename="package://new_model/meshes/RBS.STL" />
      </geometry>
      <material
        name="">
        <color
          rgba="0.75294 0.75294 0.75294 1" />
      </material>
    </visual>
    <collision>
      <origin
        xyz="0 0 0"
        rpy="0 0 0" />
      <geometry>
        <mesh
          filename="package://new_model/meshes/RBS.STL" />
      </geometry>
    </collision>
  </link>
  <joint
    name="right_back_suspension"
    type="prismatic">
    <origin
      xyz="0 0 0"
      rpy="0 0 0" />
    <parent
      link="base_link" />
    <child
      link="RBS" />
    <axis
      xyz="0 0 1" />
    <limit
      lower="0"
      upper="0"
      effort="0"
      velocity="0" />
  </joint>
  <link
    name="RBC">
    <inertial>
      <origin
        xyz="0.16321 -0.083575 0.081145"
        rpy="0 0 0" />
      <mass
        value="0.03248" />
      <inertia
        ixx="8.8659E-06"
        ixy="6.1151E-08"
        ixz="1.2061E-06"
        iyy="1.0703E-05"
        iyz="-4.0099E-08"
        izz="2.8292E-06" />
    </inertial>
    <visual>
      <origin
        xyz="0 0 0"
        rpy="0 0 0" />
      <geometry>
        <mesh
          filename="package://new_model/meshes/RBC.STL" />
      </geometry>
      <material
        name="">
        <color
          rgba="0.89804 0.91765 0.92941 1" />
      </material>
    </visual>
    <collision>
      <origin
        xyz="0 0 0"
        rpy="0 0 0" />
      <geometry>
        <mesh
          filename="package://new_model/meshes/RBC.STL" />
      </geometry>
    </collision>
  </link>
  <joint
    name="rihgt_back_castle"
    type="continuous">
    <origin
      xyz="0 0 0"
      rpy="0 0 0" />
    <parent
      link="RBS" />
    <child
      link="RBC" />
    <axis
      xyz="0 0 1" />
  </joint>
  <link
    name="RBW">
    <inertial>
      <origin
        xyz="0.18942 -0.084446 0.064353"
        rpy="0 0 0" />
      <mass
        value="0.19359" />
      <inertia
        ixx="0.00025295"
        ixy="-3.861E-06"
        ixz="-2.8371E-33"
        iyy="0.00013695"
        iyz="-1.9437E-32"
        izz="0.00013682" />
    </inertial>
    <visual>
      <origin
        xyz="0 0 0"
        rpy="0 0 0" />
      <geometry>
        <mesh
          filename="package://new_model/meshes/RBW.STL" />
      </geometry>
      <material
        name="">
        <color
          rgba="1 1 1 1" />
      </material>
    </visual>
    <collision>
      <origin
        xyz="0 0 0"
        rpy="0 0 0" />
      <geometry>
        <mesh
          filename="package://new_model/meshes/RBW.STL" />
      </geometry>
    </collision>
  </link>
  <joint
    name="right_back_wheel"
    type="continuous">
    <origin
      xyz="0 0 0"
      rpy="0 0 0" />
    <parent
      link="RBC" />
    <child
      link="RBW" />
    <axis
      xyz="0.99945 -0.033227 0" />
    <limit
      effort="3.1"
      velocity="7" />
  </joint>
  <link
    name="LBS">
    <inertial>
      <origin
        xyz="-0.12676 -0.083501 0.099498"
        rpy="0 0 0" />
      <mass
        value="0.19701" />
      <inertia
        ixx="1.688E-05"
        ixy="1.2258E-20"
        ixz="-2.3064E-19"
        iyy="5.0552E-05"
        iyz="2.9288E-21"
        izz="4.6911E-05" />
    </inertial>
    <visual>
      <origin
        xyz="0 0 0"
        rpy="0 0 0" />
      <geometry>
        <mesh
          filename="package://new_model/meshes/LBS.STL" />
      </geometry>
      <material
        name="">
        <color
          rgba="0.75294 0.75294 0.75294 1" />
      </material>
    </visual>
    <collision>
      <origin
        xyz="0 0 0"
        rpy="0 0 0" />
      <geometry>
        <mesh
          filename="package://new_model/meshes/LBS.STL" />
      </geometry>
    </collision>
  </link>
  <joint
    name="left_back_suspension"
    type="prismatic">
    <origin
      xyz="0 0 0"
      rpy="0 0 0" />
    <parent
      link="base_link" />
    <child
      link="LBS" />
    <axis
      xyz="0 0 1" />
    <limit
      lower="0"
      upper="0"
      effort="0"
      velocity="0" />
  </joint>
  <link
    name="LBC">
    <inertial>
      <origin
        xyz="-0.16321 -0.083649 0.081145"
        rpy="0 0 0" />
      <mass
        value="0.03248" />
      <inertia
        ixx="8.8721E-06"
        ixy="-1.2291E-07"
        ixz="-1.2041E-06"
        iyy="1.0697E-05"
        iyz="-8.0732E-08"
        izz="2.8292E-06" />
    </inertial>
    <visual>
      <origin
        xyz="0 0 0"
        rpy="0 0 0" />
      <geometry>
        <mesh
          filename="package://new_model/meshes/LBC.STL" />
      </geometry>
      <material
        name="">
        <color
          rgba="0.89804 0.91765 0.92941 1" />
      </material>
    </visual>
    <collision>
      <origin
        xyz="0 0 0"
        rpy="0 0 0" />
      <geometry>
        <mesh
          filename="package://new_model/meshes/LBC.STL" />
      </geometry>
    </collision>
  </link>
  <joint
    name="left_back_castle"
    type="continuous">
    <origin
      xyz="0 0 0"
      rpy="0 0 0" />
    <parent
      link="LBS" />
    <child
      link="LBC" />
    <axis
      xyz="0 0 1" />
  </joint>
  <link
    name="LBW">
    <inertial>
      <origin
        xyz="-0.18937 -0.085403 0.064353"
        rpy="0 0 0" />
      <mass
        value="0.19359" />
      <inertia
        ixx="0.00025256"
        ixy="7.7603E-06"
        ixz="8.8996E-19"
        iyy="0.00013734"
        iyz="6.1633E-20"
        izz="0.00013682" />
    </inertial>
    <visual>
      <origin
        xyz="0 0 0"
        rpy="0 0 0" />
      <geometry>
        <mesh
          filename="package://new_model/meshes/LBW.STL" />
      </geometry>
      <material
        name="">
        <color
          rgba="1 1 1 1" />
      </material>
    </visual>
    <collision>
      <origin
        xyz="0 0 0"
        rpy="0 0 0" />
      <geometry>
        <mesh
          filename="package://new_model/meshes/LBW.STL" />
      </geometry>
    </collision>
  </link>
  <joint
    name="left_back_wheel"
    type="continuous">
    <origin
      xyz="0 0 0"
      rpy="0 0 0" />
    <parent
      link="LBC" />
    <child
      link="LBW" />
    <axis
      xyz="0.99776 0.066898 0" />
    <limit
      effort="3.1"
      velocity="7" />
  </joint>
  <link
    name="webcam">
    <inertial>
      <origin
        xyz="0.010772 0.12237 0.19826"
        rpy="0 0 0" />
      <mass
        value="0.084224" />
      <inertia
        ixx="1.4022E-05"
        ixy="-9.3308E-07"
        ixz="2.9326E-08"
        iyy="2.9762E-05"
        iyz="-4.8403E-07"
        izz="3.7024E-05" />
    </inertial>
    <visual>
      <origin
        xyz="0 0 0"
        rpy="0 0 0" />
      <geometry>
        <mesh
          filename="package://new_model/meshes/webcam.STL" />
      </geometry>
      <material
        name="">
        <color
          rgba="0.75294 0.75294 0.75294 1" />
      </material>
    </visual>
    <collision>
      <origin
        xyz="0 0 0"
        rpy="0 0 0" />
      <geometry>
        <mesh
          filename="package://new_model/meshes/webcam.STL" />
      </geometry>
    </collision>
  </link>
  <joint
    name="webcam"
    type="fixed">
    <origin
      xyz="0 0 0"
      rpy="0 0 0" />
    <parent
      link="base_link" />
    <child
      link="webcam" />
    <axis
      xyz="0 0 0" />
  </joint>
  <link
    name="lidar">
    <inertial>
      <origin
        xyz="-0.0012251 -0.013214 0.15819"
        rpy="0 0 0" />
      <mass
        value="5.046" />
      <inertia
        ixx="0.019959"
        ixy="8.4963E-07"
        ixz="3.5792E-07"
        iyy="0.013378"
        iyz="-8.6941E-06"
        izz="0.020401" />
    </inertial>
    <visual>
      <origin
        xyz="0 0 0"
        rpy="0 0 0" />
      <geometry>
        <mesh
          filename="package://new_model/meshes/lidar.STL" />
      </geometry>
      <material
        name="">
        <color
          rgba="0.75294 0.75294 0.75294 1" />
      </material>
    </visual>
    <collision>
      <origin
        xyz="0 0 0"
        rpy="0 0 0" />
      <geometry>
        <mesh
          filename="package://new_model/meshes/lidar.STL" />
      </geometry>
    </collision>
  </link>
  <joint
    name="lidar"
    type="prismatic">
    <origin
      xyz="0 0 0"
      rpy="0 0 0" />
    <parent
      link="base_link" />
    <child
      link="lidar" />
    <axis
      xyz="1 0 0" />
    <limit
      lower="0"
      upper="0"
      effort="0"
      velocity="0" />
  </joint>
</robot>